<robot
  name="assem1">
  <link
    name="base_link">
    <inertial>
      <origin
        xyz="0.016193 0.0075597 0.16932"
        rpy="0 0 0" />
      <mass
        value="1.0825" />
      <inertia
        ixx="0.0024312"
        ixy="-3.6924E-07"
        ixz="-2.405E-05"
        iyy="0.0024643"
        iyz="4.5304E-07"
        izz="0.001404" />
    </inertial>
    <visual>
      <origin
        xyz="0 0 0"
        rpy="0 0 0" />
      <geometry>
        <mesh
          filename="package://assem1/meshes/base_link.STL" />
      </geometry>
      <material
        name="">
        <color
          rgba="0.79216 0.81961 0.93333 1" />
      </material>
    </visual>
    <collision>
      <origin
        xyz="0 0 0"
        rpy="0 0 0" />
      <geometry>
        <mesh
          filename="package://assem1/meshes/base_link.STL" />
      </geometry>
    </collision>
  </link>
  <link
    name="Empty_Link1">
    <inertial>
      <origin
        xyz="1.1309E-11 0.10487 -4.2875E-05"
        rpy="0 0 0" />
      <mass
        value="1.0452" />
      <inertia
        ixx="0.0036841"
        ixy="2.7729E-15"
        ixz="-2.6194E-13"
        iyy="0.001124"
        iyz="-3.2761E-06"
        izz="0.0035066" />
    </inertial>
    <visual>
      <origin
        xyz="0 0 0"
        rpy="0 0 0" />
      <geometry>
        <mesh
          filename="package://assem1/meshes/Empty_Link1.STL" />
      </geometry>
      <material
        name="">
        <color
          rgba="0.79216 0.81961 0.93333 1" />
      </material>
    </visual>
    <collision>
      <origin
        xyz="0 0 0"
        rpy="0 0 0" />
      <geometry>
        <mesh
          filename="package://assem1/meshes/Empty_Link1.STL" />
      </geometry>
    </collision>
  </link>
  <joint
    name="j1"
    type="revolute">
    <origin
      xyz="0.016815 -0.21118 0.0075661"
      rpy="3.1416 1.5708 0" />
    <parent
      link="base_link" />
    <child
      link="Empty_Link1" />
    <axis
      xyz="-1 0 0" />
    <limit
      lower="3"
      upper="3"
      effort="10"
      velocity="5" />
  </joint>
  <link
    name="Empty_Link2">
    <inertial>
      <origin
        xyz="1.8745E-05 -2.2012E-10 0.17005"
        rpy="0 0 0" />
      <mass
        value="2.3511" />
      <inertia
        ixx="0.029845"
        ixy="-1.2972E-10"
        ixz="-3.919E-06"
        iyy="0.029188"
        iyz="1.905E-10"
        izz="0.0037161" />
    </inertial>
    <visual>
      <origin
        xyz="0 0 0"
        rpy="0 0 0" />
      <geometry>
        <mesh
          filename="package://assem1/meshes/Empty_Link2.STL" />
      </geometry>
      <material
        name="">
        <color
          rgba="0.79216 0.81961 0.93333 1" />
      </material>
    </visual>
    <collision>
      <origin
        xyz="0 0 0"
        rpy="0 0 0" />
      <geometry>
        <mesh
          filename="package://assem1/meshes/Empty_Link2.STL" />
      </geometry>
    </collision>
  </link>
  <joint
    name="j2"
    type="revolute">
    <origin
      xyz="0 0.17 0"
      rpy="3.1416 -3.4694E-15 -1.5708" />
    <parent
      link="Empty_Link1" />
    <child
      link="Empty_Link2" />
    <axis
      xyz="0 1 0" />
    <limit
      lower="3"
      upper="3"
      effort="5"
      velocity="10" />
  </joint>
  <link
    name="Empty_Link3">
    <inertial>
      <origin
        xyz="-2.6021E-18 -0.027892 0"
        rpy="0 0 0" />
      <mass
        value="0.54972" />
      <inertia
        ixx="0.0013982"
        ixy="2.4899E-20"
        ixz="6.443E-20"
        iyy="0.00041621"
        iyz="6.5024E-20"
        izz="0.0012282" />
    </inertial>
    <visual>
      <origin
        xyz="0 0 0"
        rpy="0 0 0" />
      <geometry>
        <mesh
          filename="package://assem1/meshes/Empty_Link3.STL" />
      </geometry>
      <material
        name="">
        <color
          rgba="0.79216 0.81961 0.93333 1" />
      </material>
    </visual>
    <collision>
      <origin
        xyz="0 0 0"
        rpy="0 0 0" />
      <geometry>
        <mesh
          filename="package://assem1/meshes/Empty_Link3.STL" />
      </geometry>
    </collision>
  </link>
  <joint
    name="j3"
    type="revolute">
    <origin
      xyz="0 0 0.34"
      rpy="0 0 1.5708" />
    <parent
      link="Empty_Link2" />
    <child
      link="Empty_Link3" />
    <axis
      xyz="1 0 0" />
    <limit
      lower="3"
      upper="3"
      effort="5"
      velocity="10" />
  </joint>
  <link
    name="Empty_Link4">
    <inertial>
      <origin
        xyz="5.5511E-17 0.084926 -3.4694E-18"
        rpy="0 0 0" />
      <mass
        value="0.55242" />
      <inertia
        ixx="0.0015014"
        ixy="-7.1923E-22"
        ixz="-9.3833E-20"
        iyy="0.00035532"
        iyz="8.7341E-20"
        izz="0.0014817" />
    </inertial>
    <visual>
      <origin
        xyz="0 0 0"
        rpy="0 0 0" />
      <geometry>
        <mesh
          filename="package://assem1/meshes/Empty_Link4.STL" />
      </geometry>
      <material
        name="">
        <color
          rgba="0.79216 0.81961 0.93333 1" />
      </material>
    </visual>
    <collision>
      <origin
        xyz="0 0 0"
        rpy="0 0 0" />
      <geometry>
        <mesh
          filename="package://assem1/meshes/Empty_Link4.STL" />
      </geometry>
    </collision>
  </link>
  <joint
    name="j4"
    type="continuous">
    <origin
      xyz="0 -0.1 0"
      rpy="0 -1.5708 0" />
    <parent
      link="Empty_Link3" />
    <child
      link="Empty_Link4" />
    <axis
      xyz="0 -1 0" />
    <limit
      lower="3"
      upper="3"
      effort="5"
      velocity="10" />
  </joint>
  <link
    name="Empty_Link5">
    <inertial>
      <origin
        xyz="0.0093712 -3.6058E-10 9.2596E-09"
        rpy="0 0 0" />
      <mass
        value="0.11634" />
      <inertia
        ixx="3.5907E-05"
        ixy="8.2527E-12"
        ixz="-4.9497E-11"
        iyy="5.8354E-05"
        iyz="4.8694E-11"
        izz="5.99E-05" />
    </inertial>
    <visual>
      <origin
        xyz="0 0 0"
        rpy="0 0 0" />
      <geometry>
        <mesh
          filename="package://assem1/meshes/Empty_Link5.STL" />
      </geometry>
      <material
        name="">
        <color
          rgba="0.79216 0.81961 0.93333 1" />
      </material>
    </visual>
    <collision>
      <origin
        xyz="0 0 0"
        rpy="0 0 0" />
      <geometry>
        <mesh
          filename="package://assem1/meshes/Empty_Link5.STL" />
      </geometry>
    </collision>
  </link>
  <joint
    name="j5"
    type="revolute">
    <origin
      xyz="0 0.175 0"
      rpy="1.5708 8.6736E-17 1.5708" />
    <parent
      link="Empty_Link4" />
    <child
      link="Empty_Link5" />
    <axis
      xyz="0 1 0" />
    <limit
      lower="3"
      upper="3"
      effort="5"
      velocity="10" />
  </joint>
  <link
    name="Empty_Link6">
    <inertial>
      <origin
        xyz="5.2042E-18 0.019492 0"
        rpy="0 0 0" />
      <mass
        value="0.047638" />
      <inertia
        ixx="1.1093E-05"
        ixy="-3.9884E-21"
        ixz="5.7386E-21"
        iyy="2.5098E-05"
        iyz="-1.0937E-20"
        izz="1.8619E-05" />
    </inertial>
    <visual>
      <origin
        xyz="0 0 0"
        rpy="0 0 0" />
      <geometry>
        <mesh
          filename="package://assem1/meshes/Empty_Link6.STL" />
      </geometry>
      <material
        name="">
        <color
          rgba="0.79216 0.81961 0.93333 1" />
      </material>
    </visual>
    <collision>
      <origin
        xyz="0 0 0"
        rpy="0 0 0" />
      <geometry>
        <mesh
          filename="package://assem1/meshes/Empty_Link6.STL" />
      </geometry>
    </collision>
  </link>
  <joint
    name="j6"
    type="continuous">
    <origin
      xyz="0.035 0 0"
      rpy="5.5511E-15 0 -1.5708" />
    <parent
      link="Empty_Link5" />
    <child
      link="Empty_Link6" />
    <axis
      xyz="0 -1 0" />
    <limit
      lower="3"
      upper="3"
      effort="5"
      velocity="10" />
  </joint>
</robot>