<robot
  name="assem2">
  <link
    name="base_link">
    <inertial>
      <origin
        xyz="0.016193 -0.16932 0.0075597"
        rpy="0 0 0" />
      <mass
        value="1.0825" />
      <inertia
        ixx="0.0024312"
        ixy="0"
        ixz="0"
        iyy="0.001404"
        iyz="0"
        izz="0.0024643" />
    </inertial>
    <visual>
      <origin
        xyz="0 0 0"
        rpy="0 0 0" />
      <geometry>
        <mesh
          filename="package://assem2/meshes/base_link.STL" />
      </geometry>
      <material
        name="">
        <color
          rgba="1 0.81961 0.93333 1" />
      </material>
    </visual>
    <collision>
      <origin
        xyz="0 0 0"
        rpy="0 0 0" />
      <geometry>
        <mesh
          filename="package://assem2/meshes/base_link.STL" />
      </geometry>
    </collision>
  </link>
  <link
    name="Empty_Link1">
    <inertial>
      <origin
        xyz="0 0.10487 0"
        rpy="0 0 0" />
      <mass
        value="1.0452" />
      <inertia
        ixx="0.0036841"
        ixy="0"
        ixz="0"
        iyy="0.001124"
        iyz="0"
        izz="0.0035066" />
    </inertial>
    <visual>
      <origin
        xyz="0 0 0"
        rpy="0 0 0" />
      <geometry>
        <mesh
          filename="package://assem2/meshes/Empty_Link1.STL" />
      </geometry>
      <material
        name="">
        <color
          rgba="0.79216 0.81961 0.93333 1" />
      </material>
    </visual>
    <collision>
      <origin
        xyz="0 0 0"
        rpy="0 0 0" />
      <geometry>
        <mesh
          filename="package://assem2/meshes/Empty_Link1.STL" />
      </geometry>
    </collision>
  </link>
  <joint
    name="j1"
    type="revolute">
    <origin
      xyz="0 0 0"
      rpy="3.1416 1.5708 0" />
    <parent
      link="base_link" />
    <child
      link="Empty_Link1" />
    <axis
      xyz="-1 0 0" />
    <limit
      lower="3"
      upper="3"
      effort="5"
      velocity="10" />
  </joint>
  <link
    name="Empty_Link2">
    <inertial>
      <origin
        xyz="1.8745E-05 0 0.17005"
        rpy="0 0 0" />
      <mass
        value="2.3511" />
      <inertia
        ixx="0.029845"
        ixy="0"
        ixz="0"
        iyy="0.029188"
        iyz="1.905E-10"
        izz="0.0037161" />
    </inertial>
    <visual>
      <origin
        xyz="0 0 0"
        rpy="0 0 0" />
      <geometry>
        <mesh
          filename="package://assem2/meshes/Empty_Link2.STL" />
      </geometry>
      <material
        name="">
        <color
          rgba="0.79216 1 0.93333 1" />
      </material>
    </visual>
    <collision>
      <origin
        xyz="0 0 0"
        rpy="0 0 0" />
      <geometry>
        <mesh
          filename="package://assem2/meshes/Empty_Link2.STL" />
      </geometry>
    </collision>
  </link>
  <joint
    name="j2"
    type="revolute">
    <origin
      xyz="0 0.17 0"
      rpy="3.1416 0 -1.5708" />
    <parent
      link="Empty_Link1" />
    <child
      link="Empty_Link2" />
    <axis
      xyz="0 1 0" />
    <limit
      lower="3"
      upper="3"
      effort="5"
      velocity="10" />
  </joint>
  <link
    name="Empty_Link3">
    <inertial>
      <origin
        xyz="0 -0.027892 0"
        rpy="0 0 0" />
      <mass
        value="0.54972" />
      <inertia
        ixx="0.0013982"
        ixy="0"
        ixz="0"
        iyy="0.00041621"
        iyz="0"
        izz="0.0012282" />
    </inertial>
    <visual>
      <origin
        xyz="0 0 0"
        rpy="0 0 0" />
      <geometry>
        <mesh
          filename="package://assem2/meshes/Empty_Link3.STL" />
      </geometry>
      <material
        name="">
        <color
          rgba="0.79216 0.81961 0.93333 1" />
      </material>
    </visual>
    <collision>
      <origin
        xyz="0 0 0"
        rpy="0 0 0" />
      <geometry>
        <mesh
          filename="package://assem2/meshes/Empty_Link3.STL" />
      </geometry>
    </collision>
  </link>
  <joint
    name="j3"
    type="revolute">
    <origin
      xyz="0 0 0.34"
      rpy="0 0 1.5708" />
    <parent
      link="Empty_Link2" />
    <child
      link="Empty_Link3" />
    <axis
      xyz="1 0 0" />
    <limit
      lower="3"
      upper="3"
      effort="5"
      velocity="10" />
  </joint>
  <link
    name="Empty_Link4">
    <inertial>
      <origin
        xyz="0 0.084926 0"
        rpy="0 0 0" />
      <mass
        value="0.55242" />
      <inertia
        ixx="0.0015014"
        ixy="0"
        ixz="0"
        iyy="0.00035532"
        iyz="0"
        izz="0.0014817" />
    </inertial>
    <visual>
      <origin
        xyz="0 0 0"
        rpy="0 0 0" />
      <geometry>
        <mesh
          filename="package://assem2/meshes/Empty_Link4.STL" />
      </geometry>
      <material
        name="">
        <color
          rgba="0.6 0.41 1 1" />
      </material>
    </visual>
    <collision>
      <origin
        xyz="0 0 0"
        rpy="0 0 0" />
      <geometry>
        <mesh
          filename="package://assem2/meshes/Empty_Link4.STL" />
      </geometry>
    </collision>
  </link>
  <joint
    name="j4"
    type="continuous">
    <origin
      xyz="0 -0.1 0"
      rpy="0 -1.5708 0" />
    <parent
      link="Empty_Link3" />
    <child
      link="Empty_Link4" />
    <axis
      xyz="0 -1 0" />
    <limit
      lower="3"
      upper="3"
      effort="5"
      velocity="10" />
  </joint>
  <link
    name="Empty_Link5">
    <inertial>
      <origin
        xyz="0.0093712 0 0"
        rpy="0 0 0" />
      <mass
        value="0.11634" />
      <inertia
        ixx="0"
        ixy="0"
        ixz="0"
        iyy="0"
        iyz="0"
        izz="0" />
    </inertial>
    <visual>
      <origin
        xyz="0 0 0"
        rpy="0 0 0" />
      <geometry>
        <mesh
          filename="package://assem2/meshes/Empty_Link5.STL" />
      </geometry>
      <material
        name="">
        <color
          rgba="0.79216 0.81961 0.93333 1" />
      </material>
    </visual>
    <collision>
      <origin
        xyz="0 0 0"
        rpy="0 0 0" />
      <geometry>
        <mesh
          filename="package://assem2/meshes/Empty_Link5.STL" />
      </geometry>
    </collision>
  </link>
  <joint
    name="j5"
    type="revolute">
    <origin
      xyz="0 0.175 0"
      rpy="1.5708 0 1.5708" />
    <parent
      link="Empty_Link4" />
    <child
      link="Empty_Link5" />
    <axis
      xyz="0 1 0" />
    <limit
      lower="3"
      upper="3"
      effort="5"
      velocity="10" />
  </joint>
  <link
    name="Empty_Link6">
    <inertial>
      <origin
        xyz="0 0.019492 0"
        rpy="0 0 0" />
      <mass
        value="0.047638" />
      <inertia
        ixx="0"
        ixy="0"
        ixz="0"
        iyy="0"
        iyz="0"
        izz="0" />
    </inertial>
    <visual>
      <origin
        xyz="0 0 0"
        rpy="0 0 0" />
      <geometry>
        <mesh
          filename="package://assem2/meshes/Empty_Link6.STL" />
      </geometry>
      <material
        name="">
        <color
          rgba="0.79216 0.81961 0.93333 1" />
      </material>
    </visual>
    <collision>
      <origin
        xyz="0 0 0"
        rpy="0 0 0" />
      <geometry>
        <mesh
          filename="package://assem2/meshes/Empty_Link6.STL" />
      </geometry>
    </collision>
  </link>
  <joint
    name="j6"
    type="continuous">
    <origin
      xyz="0.035 0 0"
      rpy="0 0 -1.5708" />
    <parent
      link="Empty_Link5" />
    <child
      link="Empty_Link6" />
    <axis
      xyz="0 -1 0" />
    <limit
      lower="3"
      upper="3"
      effort="5"
      velocity="10" />
  </joint>
</robot>