<robot
  name="assem3">
  <link
    name="base_link">
    <inertial>
      <origin
        xyz="-0.00062202 -6.3729E-06 0.068137"
        rpy="0 0 0" />
      <mass
        value="1.0825" />
      <inertia
        ixx="0.0024312"
        ixy="-3.6924E-07"
        ixz="-2.405E-05"
        iyy="0.0024643"
        iyz="4.5304E-07"
        izz="0.001404" />
    </inertial>
    <visual>
      <origin
        xyz="0 0 0"
        rpy="0 0 0" />
      <geometry>
        <mesh
          filename="package://assem3/meshes/base_link.STL" />
      </geometry>
      <material
        name="">
        <color
          rgba="0.79216 0.81961 0.93333 1" />
      </material>
    </visual>
    <collision>
      <origin
        xyz="0 0 0"
        rpy="0 0 0" />
      <geometry>
        <mesh
          filename="package://assem3/meshes/base_link.STL" />
      </geometry>
    </collision>
  </link>
  <link
    name="Empty_Link1">
    <inertial>
      <origin
        xyz="4.2875E-05 -1.1309E-11 0.10487"
        rpy="0 0 0" />
      <mass
        value="1.0452" />
      <inertia
        ixx="0.0035066"
        ixy="-2.6194E-13"
        ixz="3.2761E-06"
        iyy="0.0036841"
        iyz="-2.7729E-15"
        izz="0.001124" />
    </inertial>
    <visual>
      <origin
        xyz="0 0 0"
        rpy="0 0 0" />
      <geometry>
        <mesh
          filename="package://assem3/meshes/Empty_Link1.STL" />
      </geometry>
      <material
        name="">
        <color
          rgba="0.79216 0.81961 0.93333 1" />
      </material>
    </visual>
    <collision>
      <origin
        xyz="0 0 0"
        rpy="0 0 0" />
      <geometry>
        <mesh
          filename="package://assem3/meshes/Empty_Link1.STL" />
      </geometry>
    </collision>
  </link>
  <joint
    name="j1"
    type="revolute">
    <origin
      xyz="0 0 0.11"
      rpy="0 0 0" />
    <parent
      link="base_link" />
    <child
      link="Empty_Link1" />
    <axis
      xyz="0 0 1" />
    <limit
      effort="0"
      velocity="0" />
  </joint>
  <link
    name="Empty_Link2">
    <inertial>
      <origin
        xyz="0.17005 -2.2012E-10 -1.8745E-05"
        rpy="0 0 0" />
      <mass
        value="2.3511" />
      <inertia
        ixx="0.0037161"
        ixy="1.905E-10"
        ixz="3.919E-06"
        iyy="0.029188"
        iyz="1.2972E-10"
        izz="0.029845" />
    </inertial>
    <visual>
      <origin
        xyz="0 0 0"
        rpy="0 0 0" />
      <geometry>
        <mesh
          filename="package://assem3/meshes/Empty_Link2.STL" />
      </geometry>
      <material
        name="">
        <color
          rgba="0.79216 0.81961 0.93333 1" />
      </material>
    </visual>
    <collision>
      <origin
        xyz="0 0 0"
        rpy="0 0 0" />
      <geometry>
        <mesh
          filename="package://assem3/meshes/Empty_Link2.STL" />
      </geometry>
    </collision>
  </link>
  <joint
    name="j2"
    type="revolute">
    <origin
      xyz="0 0 0.17"
      rpy="0 0 0" />
    <parent
      link="Empty_Link1" />
    <child
      link="Empty_Link2" />
    <axis
      xyz="0 1 0" />
    <limit
      effort="0"
      velocity="0" />
  </joint>
  <link
    name="Empty_Link3">
    <inertial>
      <origin
        xyz="0 -2.6021E-18 -0.027892"
        rpy="0 0 0" />
      <mass
        value="0.54972" />
      <inertia
        ixx="0.0012282"
        ixy="6.4106E-20"
        ixz="6.3159E-20"
        iyy="0.0013982"
        iyz="2.8165E-20"
        izz="0.00041621" />
    </inertial>
    <visual>
      <origin
        xyz="0 0 0"
        rpy="0 0 0" />
      <geometry>
        <mesh
          filename="package://assem3/meshes/Empty_Link3.STL" />
      </geometry>
      <material
        name="">
        <color
          rgba="0.79216 0.81961 0.93333 1" />
      </material>
    </visual>
    <collision>
      <origin
        xyz="0 0 0"
        rpy="0 0 0" />
      <geometry>
        <mesh
          filename="package://assem3/meshes/Empty_Link3.STL" />
      </geometry>
    </collision>
  </link>
  <joint
    name="j3"
    type="revolute">
    <origin
      xyz="0.34 0 0"
      rpy="0 0 0" />
    <parent
      link="Empty_Link2" />
    <child
      link="Empty_Link3" />
    <axis
      xyz="0 1 0" />
    <limit
      effort="0"
      velocity="0" />
  </joint>
  <link
    name="Empty_Link4">
    <inertial>
      <origin
        xyz="5.5511E-17 3.4694E-18 -0.084926"
        rpy="0 0 0" />
      <mass
        value="0.55242" />
      <inertia
        ixx="0.0015014"
        ixy="-9.3885E-20"
        ixz="5.0286E-21"
        iyy="0.0014817"
        iyz="1.1207E-20"
        izz="0.00035532" />
    </inertial>
    <visual>
      <origin
        xyz="0 0 0"
        rpy="0 0 0" />
      <geometry>
        <mesh
          filename="package://assem3/meshes/Empty_Link4.STL" />
      </geometry>
      <material
        name="">
        <color
          rgba="0.79216 0.81961 0.93333 1" />
      </material>
    </visual>
    <collision>
      <origin
        xyz="0 0 0"
        rpy="0 0 0" />
      <geometry>
        <mesh
          filename="package://assem3/meshes/Empty_Link4.STL" />
      </geometry>
    </collision>
  </link>
  <joint
    name="j4"
    type="continuous">
    <origin
      xyz="0 0 -0.1"
      rpy="0 0 0" />
    <parent
      link="Empty_Link3" />
    <child
      link="Empty_Link4" />
    <axis
      xyz="0 0 1" />
  </joint>
  <link
    name="Empty_Link5">
    <inertial>
      <origin
        xyz="9.2596E-09 -3.6058E-10 -0.0093712"
        rpy="0 0 0" />
      <mass
        value="0.11634" />
      <inertia
        ixx="5.99E-05"
        ixy="4.8694E-11"
        ixz="4.9497E-11"
        iyy="5.8354E-05"
        iyz="-8.2527E-12"
        izz="3.5907E-05" />
    </inertial>
    <visual>
      <origin
        xyz="0 0 0"
        rpy="0 0 0" />
      <geometry>
        <mesh
          filename="package://assem3/meshes/Empty_Link5.STL" />
      </geometry>
      <material
        name="">
        <color
          rgba="0.79216 0.81961 0.93333 1" />
      </material>
    </visual>
    <collision>
      <origin
        xyz="0 0 0"
        rpy="0 0 0" />
      <geometry>
        <mesh
          filename="package://assem3/meshes/Empty_Link5.STL" />
      </geometry>
    </collision>
  </link>
  <joint
    name="j5"
    type="revolute">
    <origin
      xyz="0 0 -0.175"
      rpy="0 0 0" />
    <parent
      link="Empty_Link4" />
    <child
      link="Empty_Link5" />
    <axis
      xyz="0 1 0" />
    <limit
      effort="0"
      velocity="0" />
  </joint>
  <link
    name="Empty_Link6">
    <inertial>
      <origin
        xyz="1.1102E-16 -5.2042E-18 -0.019492"
        rpy="0 0 0" />
      <mass
        value="0.047638" />
      <inertia
        ixx="1.8619E-05"
        ixy="-5.7386E-21"
        ixz="-2.4923E-20"
        iyy="1.1093E-05"
        iyz="-4.0208E-21"
        izz="2.5098E-05" />
    </inertial>
    <visual>
      <origin
        xyz="0 0 0"
        rpy="0 0 0" />
      <geometry>
        <mesh
          filename="package://assem3/meshes/Empty_Link6.STL" />
      </geometry>
      <material
        name="">
        <color
          rgba="0.79216 0.81961 0.93333 1" />
      </material>
    </visual>
    <collision>
      <origin
        xyz="0 0 0"
        rpy="0 0 0" />
      <geometry>
        <mesh
          filename="package://assem3/meshes/Empty_Link6.STL" />
      </geometry>
    </collision>
  </link>
  <joint
    name="j6"
    type="continuous">
    <origin
      xyz="0 0 -0.035"
      rpy="0 0 0" />
    <parent
      link="Empty_Link5" />
    <child
      link="Empty_Link6" />
    <axis
      xyz="0 0 1" />
  </joint>
</robot>